{"name": "Ошибка при попытке повторного создания существующего пользователя", "status": "passed", "start": 1717592828267, "stop": 1717592828439, "uuid": "9c3af1ef-352f-4798-95c2-60df583f5e83", "historyId": "c1e9f38a3f3f2563cf68ba2e3b34a03c", "testCaseId": "c1e9f38a3f3f2563cf68ba2e3b34a03c", "fullName": "tests.py.test_user.TestUserCreating#test_register_double_user_failed_result", "labels": [{"name": "parentSuite", "value": "tests.py"}, {"name": "suite", "value": "test_user"}, {"name": "subSuite", "value": "TestUserCreating"}, {"name": "host", "value": "DESKTOP-AQPR8BL"}, {"name": "thread", "value": "6544-MainThread"}, {"name": "framework", "value": "pytest"}, {"name": "language", "value": "cpython3"}, {"name": "package", "value": "tests.py.test_user"}]}