{"name": "Ошибка при попытке повторного создания существующего пользователя", "status": "passed", "start": 1717767610648, "stop": 1717767610985, "uuid": "4edb6e06-61cf-4b4b-b8a3-d28760cef343", "historyId": "c1e9f38a3f3f2563cf68ba2e3b34a03c", "testCaseId": "c1e9f38a3f3f2563cf68ba2e3b34a03c", "fullName": "tests.py.test_user.TestUserCreating#test_register_double_user_failed_result", "labels": [{"name": "parentSuite", "value": "tests.py"}, {"name": "suite", "value": "test_user"}, {"name": "subSuite", "value": "TestUserCreating"}, {"name": "host", "value": "DESKTOP-AQPR8BL"}, {"name": "thread", "value": "16524-MainThread"}, {"name": "framework", "value": "pytest"}, {"name": "language", "value": "cpython3"}, {"name": "package", "value": "tests.py.test_user"}]}